Workbook

Sheet CONCENTRADO
A1: CONCENTRADO GENERAL | AO1: MEDIA
F2: CAMPIMETRIA | J2: AUDIOMETRÍA | R2: RADIOGRAFIA COLUMNA | V2: RADIOGRAFIA TORAX
A3: FOLIO | B3: NOMBRE | C3: SEXO | D3: AREA/ PUESTO | E3: ANTIGÜEDAD | F3: AGUDEZA VISUAL | G3: CAMPOS VISUALES | H3: DISCRIMINACION DEL COLOR | I3: DX | J3: OIDO DERECHO | K3: OIDO IZQUIERDO | L3: % HBC | M3: ESPIROMETRIA | N3: FVC | O3: TABAQUISMO | P3: ELECTROCARDIOGRAMA | Q3: VALORACION POSTURAL | R3: GRADO DE ESCOLIOSIS(°) | S3: GRADO DE LORDOSIS(°) | T3: BASCULACIÓN PELVICA (cms) | U3: IMPRESIÓN DIAGNOSTICA | V3: IMPRESIÓN DIAGNOSTICA
A4: 168058 | B4: AGUILAR ARREOLA JOSE DAVID | C4: MASCULINO | D4: SOLDADURA | E4: 3 AÑOS 9 MESES | F4: DISMINUIDA SIN USO DE LENTES | G4: NORMAL | H4: NORMAL | I4: NORMAL | J4: Audición Normal | K4: Audición Normal | L4: -1.25 | M4: NORMAL | N4: 0.93 | O4: NEGADO | P4: Electrocardiograma en reposo sin datos de anormalidad al momento del estudio | Q4: 1.- CUELLO CORTO. 2.- HIPERCIFOSIS CERVICAL. 3.- HIPERLORDOSIS. 4.- GENU VALGO. 5.- HALLUX VALGUX. | R4: 3 | S4: 36 | T4: 0 | U4: DESVIACION LEVOCONVEXA LUMBOSACRA ( 3 ° ) CON LORDOSIS NORMAL Y CON ANGULO DE 36 °. NO SE IDENTIFICAN FRACTURAS NI TUMORACIONES. | V4: TORAX RADIOLOGICAMENTE NORMAL, SIN EVIDENCIA DE PATOLOGÍA AGUDA O EVOLUTIVA APARENTE. | AO4: =AVERAGE(#REF!,#REF!) -> #REF!
A5: 168055 | B5: ALDABALDE MARTINEZ SAUL | C5: MASCULINO | D5: SOLDADURA | E5: 3 AÑOS 6 MESES | F5: DISMINUIDA SIN USO DE LENTES | G5: NORMAL | H5: NORMAL | I5: FATIGA AUDITIVA | J5: Audición Normal, Datos de Fatiga Auditiva | K5: Audición Normal, Datos de Fatiga Auditiva | L5: 2.88 | M5: NORMAL | N5: 0.91 | O5: NEGADO | P5: Electrocardiograma en reposo sin datos de anormalidad al momento del estudio | Q5: 1.- ASCENSO DE HOMBRO IZQUIERDO. 2.- HIPERCIFOSIS CERVICAL. 3.- HIPERLORDOSIS. | R5: 3 | S5: 40 | T5: 0 | U5: DESVIACION DEXTROCONVEXA LUMBOSACRA ( 3 ° ) CON HIPERLORDOSIS Y CON ANGULO DE 40 °. ESTRECHAMIENTO L4-5-S1 NO SE IDENTIFICAN FRACTURAS NI TUMORACIONES. | V5: TORAX RADIOLOGICAMENTE NORMAL, SIN EVIDENCIA DE PATOLOGÍA AGUDA O EVOLUTIVA APARENTE. PROB. GRANULOMA PARAHILIAR DERECHO. | AO5: =AVERAGE(#REF!,#REF!) -> #REF!
A6: 168182 | B6: ANGEL MATA JOHAN EDGAR | C6: MASCULINO | D6: MANTENIMIENTO | E6: 2 AÑOS | F6: NORMAL | G6: NORMAL | H6: NORMAL | I6: FATIGA AUDITIVA | J6: Audición Normal | K6: Audición Normal, Datos de Fatiga Auditiva | L6: 5.5 | M6: PATRÓN ESPIROMÉTRICO RESTRICTIVO LEVE | N6: 0.76 | O6: POSITIVO | P6: Electrocardiograma en reposo sin datos de anormalidad al momento del estudio | Q6: 1,-ALINEACION POSTURAL NORMAL. | R6: 3 | S6: 30 | T6: 0 | U6: DESVIACION LEVOCONVEXA LUMBOSACRA ( 3 ° ) CON LORDOSIS NORMAL Y CON ANGULO DE 30 °. LIGERO PINZAMIENTO L5-S1. NO SE IDENTIFICAN FRACTURAS NI TUMORACIONES. | V6: TORAX RADIOLOGICAMENTE NORMAL, SIN EVIDENCIA DE PATOLOGÍA AGUDA O EVOLUTIVA APARENTE. | AO6: =AVERAGE(#REF!,#REF!) -> #REF!
A7: 168023 | B7: ARREDONDO ORTIZ VIRTOR HUGO | C7: MASCULINO | D7: MAQUINADOS | E7: 4 AÑOS | F7: NORMAL | G7: NORMAL | H7: NORMAL | I7: FATIGA AUDITIVA | J7: Audición Normal, Datos de Fatiga Auditiva | K7: Audición Normal, Datos de Fatiga Auditiva | L7: 3.38 | M7: NORMAL | N7: 0.85 | O7: NEGADO | P7: Electrocardiograma en reposo sin datos de anormalidad al momento del estudio | Q7: 1.-HIPERLORDOSIS 2.-GENU RECURVATUM. | R7: 5 | S7: 40 | T7: 0 | U7: DESVIACION DEXTROCONVEXA LUMBOSACRA ( 5 ° ) CON HIPERLORDOSIS Y CON ANGULO DE 40 °. PINZAMIENTO L-5-S1 NO SE IDENTIFICAN FRACTURAS NI TUMORACIONES. | V7: TORAX RADIOLOGICAMENTE NORMAL, SIN EVIDENCIA DE PATOLOGÍA AGUDA O EVOLUTIVA APARENTE. | AO7: =AVERAGE(#REF!,#REF!) -> #REF!
A8: 168151 | B8: BOLAÑOS PALACIOS MIREYA | C8: FEMENINO | D8: MANTENIMIENTO | E8: 1 AÑO | F8: N/A | G8: N/A | H8: N/A | I8: NORMAL | J8: Audición Normal | K8: Audición Normal | L8: 3.13 | M8: N/A | N8: N/A | O8: NEGADO | P8: N/A | Q8: 1.- HIPERLORDOSIS. | R8: 3 | S8: 45 | T8: 0 | U8: DESVIACION LEVOCONVEXA LUMBOSACRA ( 3° ) CON HIPERLORDOSIS, INESTABILIDAD LUMBAR Y CON ANGULO DE 45°. BOSTEZO Y LIGERO PINZAMIENTO L5-S1. NO SE IDENTIFICAN FRACTURAS NI TUMORACIONES. | V8: N/A | AO8: =AVERAGE(#REF!,#REF!) -> #REF!
A9: 168092 | B9: CANO NAVA HUMBERTO | C9: MASCULINO | D9: SOLDADURA | E9: 4 AÑOS 10 MESES | F9: NORMAL | G9: NORMAL | H9: NORMAL | I9: LEVE TA | J9: Hipoacusia Neurosensorial, Leve , Sugestivo de Trauma Acústico crónico por ruido | K9: Audición Normal, Datos de Fatiga Auditiva | L9: 8 | M9: NORMAL | N9: 1 | O9: POSITIVO | P9: Bradicardia sinusal, resto del estudio sin datos de anormalidad al momento del estudio | Q9: 1.- HIPERLORDOSIS. | R9: 2 | S9: 46 | T9: 0 | U9: DESVIACION DEXTROCONVEXA LUMBOSACRA ( 2 ° ) CON HIPERLORDOSIS, INESTABILIDAD LUMBAR Y CON ANGULO DE 46 °. PINZAMIENTO L5-S1. NO SE IDENTIFICAN FRACTURAS NI TUMORACIONES. | V9: TORAX RADIOLOGICAMENTE NORMAL, SIN EVIDENCIA DE PATOLOGÍA AGUDA O EVOLUTIVA APARENTE. | AO9: =AVERAGE(#REF!,#REF!) -> #REF!
A10: 168107 | B10: CORDOBA BANDA MARIO FERNANDO | C10: MASCULINO | D10: SOLDADURA | E10: 4 AÑOS | F10: NORMAL | G10: NORMAL | H10: NORMAL | I10: NORMAL | J10: Audición Normal | K10: Audición Normal | L10: 3.38 | M10: NORMAL | N10: FEV1: 88% | O10: NEGADO | P10: Electrocardiograma en reposo sin datos de anormalidad al momento del estudio | Q10: 1.- GENUVARO. 2.- HIPERLORDOSIS. | R10: 3 | S10: 45 | T10: 0 | U10: DESVIACION DEXTROCONVEXA LUMBOSACRA ( 3 ° ) CON HIPERLORDOSIS, INESTABILIDAD LUMBAR Y CON ANGULO DE 45 °. NO SE IDENTIFICAN FRACTURAS NI TUMORACIONES. | V10: TORAX RADIOLOGICAMENTE NORMAL, SIN EVIDENCIA DE PATOLOGÍA AGUDA O EVOLUTIVA APARENTE. | AO10: =AVERAGE(#REF!,#REF!) -> #REF!
A11: 168132 | B11: CORREA CRUZ HUGO ABISAI | C11: MASCULINO | D11: SOLDADURA | E11: 3 AÑOS | F11: NORMAL | G11: NORMAL | H11: NORMAL | I11: LEVE TA | J11: Hipoacusia Neurosensorial, Leve , Sugestivo de Trauma Acústico crónico por ruido | K11: Hipoacusia Neurosensorial, Leve, Sugestivo de Trauma Acústico crónico por ruido | L11: 9.13 | M11: PATRÓN ESPIROMÉTRICO RESTRICTIVO LEVE | N11: 0.77 | O11: NEGADO | P11: Electrocardiograma en reposo sin datos de anormalidad al momento del estudio | Q11: 1.- HIPERLORDOSIS. 2.- ANTEVERSION PELVICA. | R11: 3 | S11: 44 | T11: 0 | U11: DESVIACION DEXTROCONVEXA LUMBOSACRA ( 3 ° ) CON HIPERLORDOSIS Y CON ANGULO DE 44 °. NO SE IDENTIFICAN FRACTURAS NI TUMORACIONES. | V11: TORAX RADIOLOGICAMENTE NORMAL, SIN EVIDENCIA DE PATOLOGÍA AGUDA O EVOLUTIVA APARENTE. | AO11: =AVERAGE(#REF!,#REF!) -> #REF!
A12: 168146 | B12: CRUZ MARTINEZ EDUARDO MISAEL | C12: MASCULINO | D12: ALMACEN F5 | E12: 3 AÑOS | F12: DISMINUIDA SIN USO DE LENTES | G12: NORMAL | H12: NORMAL | I12: NORMAL | J12: Audición Normal | K12: Audición Normal | L12: 3.38 | M12: PATRÓN ESPIROMÉTRICO RESTRICTIVO LEVE | N12: 0.73 | O12: NEGADO | P12: Electrocardiograma en reposo sin datos de anormalidad al momento del estudio | Q12: 1.-HIPERLORDOSIS 2.- PIE PLANO | R12: 5 | S12: 44 | T12: 1 | U12: DESVIACION LEVOCONVEXA LUMBOSACRA ( 5 ° ) CON HIPERLORDOSIS, INESTABILIDAD LUMBAR Y CON ANGULO DE 44 °. PINZAMIENTO L5-S1. NO SE IDENTIFICAN FRACTURAS NI TUMORACIONES. BASCULACION PELVICA IZQUIERDA DE 1.0 cm. | V12: TORAX RADIOLOGICAMENTE NORMAL, SIN EVIDENCIA DE PATOLOGÍA AGUDA O EVOLUTIVA APARENTE. | AO12: =AVERAGE(#REF!,#REF!) -> #REF!
A13: 168094 | B13: DE LA CRUZ PEREZ JUAN CARLOS | C13: MASCULINO | D13: SOLDADURA | E13: 4 AÑOS | F13: DISMINUIDA NO CORREGIDA | G13: NORMAL | H13: NORMAL | I13: LEVE TA | J13: Hipoacusia Neurosensorial, Leve , Sugestivo de Trauma Acústico crónico por ruido | K13: Audición Normal | L13: 10.38 | M13: PATRÓN ESPIROMÉTRICO RESTRICTIVO LEVE | N13: 0.74 | O13: NEGADO | P13: Electrocardiograma en reposo sin datos de anormalidad al momento del estudio | Q13: 1.- HIPERLORDOSIS | R13: 6 | S13: 40 | T13: 0 | U13: DESVIACION DEXTROCONVEXA LUMBOSACRA ( 6 ° ) CON HIPERLORDOSIS Y CON ANGULO DE 40 °. BOSTEZO L5-S1. NO SE IDENTIFICAN FRACTURAS NI TUMORACIONES. | V13: TORAX RADIOLOGICAMENTE NORMAL, SIN EVIDENCIA DE PATOLOGÍA AGUDA O EVOLUTIVA APARENTE. | AO13: =AVERAGE(#REF!,#REF!) -> #REF!
A14: 168100 | B14: DE LUNA MORALES ANGEL EDUARDO | C14: MASCULINO | D14: MAQUINADOS | E14: 5 AÑOS | F14: NORMAL | G14: NORMAL | H14: NORMAL | I14: FATIGA AUDITIVA | J14: Audición Normal | K14: Audición Normal, Datos de Fatiga Auditiva | L14: -0.5 | M14: NORMAL | N14: 0.86 | O14: NEGADO | P14: Electrocardiograma en reposo sin datos de anormalidad al momento del estudio | Q14: 1.- HIPERLORDOSIS | R14: 5 | S14: 36 | T14: 0 | U14: DESVIACION LEVOCONVEXA LUMBOSACRA ( 5 ° ) CON LORDOSIS NORMAL Y CON ANGULO DE 36 °. PINZAMIENTO L5-S1. NO SE IDENTIFICAN FRACTURAS NI TUMORACIONES. | V14: TORAX RADIOLOGICAMENTE NORMAL, SIN EVIDENCIA DE PATOLOGÍA AGUDA O EVOLUTIVA APARENTE. | AO14: =AVERAGE(#REF!,#REF!) -> #REF!
A15: 168178 | B15: DEL AGUA SUAREZ JOSE ISRAEL | C15: MASCULINO | D15: PINTURA | E15: 11 MESES | F15: NORMAL | G15: NORMAL | H15: NORMAL | I15: NORMAL | J15: Audición Normal | K15: Audición Normal | L15: 4.5 | M15: NORMAL | N15: 0.8 | O15: NEGADO | P15: Bradicardia sinusal, resto del estudio sin datos de anormalidad al momento del estudio | Q15: 1.- PIE PLANO. | R15: 4 | S15: 34 | T15: 0 | U15: DESVIACION DEXTROCONVEXA LUMBOSACRA ( 4 ° ) CON LORDOSIS NORMAL Y CON ANGULO DE 34 °. LIGERO ESTRECHAMIENTO L5-S1. NO SE IDENTIFICAN FRACTURAS NI TUMORACIONES. | V15: TORAX RADIOLOGICAMENTE NORMAL, SIN EVIDENCIA DE PATOLOGÍA AGUDA O EVOLUTIVA APARENTE. | AO15: =AVERAGE(#REF!,#REF!) -> #REF!
A16: 168175 | B16: ENRIQUEZ FAJARDO VICENTE ANTONIO | C16: MASCULINO | D16: LOGISTICA | E16: 5 AÑOS | F16: N/A | G16: N/A | H16: N/A | I16: NORMAL | J16: Audición Normal | K16: Audición Normal | L16: 5.5 | M16: N/A | N16: N/A | O16: NEGADO | P16: N/A | Q16: 1.-HIPERLORDOSIS LUMBAR. 2.- ANTEVERSION PELVICA. 3.- GENU-RECURVATUM | R16: 4 | S16: 58 | T16: 1.4 | U16: DESVIACION DEXTROCONVEXA LUMBOSACRA ( 4 ° ) CON HIPERLORDOSIS, INESTABILIDAD LUMBAR Y CON ANGULO DE 58 °. LIGERO PINZAMIENTO L5-S1. NO SE IDENTIFICAN FRACTURAS NI TUMORACIONES. BASCULACION PELVICA DERECHA DE 1.4 cm. | V16: N/A | AO16: =AVERAGE(#REF!,#REF!) -> #REF!
A17: 168041 | B17: GARCIA PACHUCA LUIS FERNANDO | C17: MASCULINO | D17: MAQUINADOS | E17: 2 AÑOS | F17: NORMAL | G17: NORMAL | H17: NORMAL | I17: NORMAL | J17: Audición Normal | K17: Audición Normal | L17: 5.5 | M17: NORMAL | N17: 0.85 | O17: NEGADO | P17: Electrocardiograma en reposo sin datos de anormalidad al momento del estudio | Q17: 1.- HIPERCIFOSIS CERVICAL. 2.- ASCENSO DE PLIEGUE DE GLUTEO IZQUIERDO 3.- LORDOSIS LUMBAR | R17: 3 | S17: 40 | T17: 0 | U17: DESVIACION DEXTROCONVEXA LUMBOSACRA ( 3 ° ) CON HIPERLORDOSIS Y CON ANGULO DE 40 °. PINZAMIENTO L-5-S1 NO SE IDENTIFICAN FRACTURAS NI TUMORACIONES. | V17: TORAX RADIOLOGICAMENTE NORMAL, SIN EVIDENCIA DE PATOLOGÍA AGUDA O EVOLUTIVA APARENTE. | AO17: =AVERAGE(#REF!,#REF!) -> #REF!
A18: 168016 | B18: GOMEZ LUCIO JOSE MANUEL | C18: MASCULINO | D18: SOLDADURA | E18: 4 AÑOS 6 MESES | F18: NORMAL | G18: NORMAL | H18: NORMAL | I18: FATIGA AUDITIVA | J18: Audición Normal, Datos de Fatiga Auditiva | K18: Audición Normal, Datos de Fatiga Auditiva | L18: 4.13 | M18: NORMAL | N18: 0.87 | O18: POSITIVO | P18: Bradicardia sinusal, resto del estudio sin datos de anormalidad al momento del estudio | Q18: 1.- ANTEPULSION DE HOMBRO DERECHO. 2.- HIPERLORDOSIS. | R18: 3 | S18: 36 | T18: 0 | U18: DESVIACION DEXTROCONVEXA LUMBOSACRA ( 3 ° ) CON LORDOSIS NORMAL Y CON ANGULO DE 36 °. NO SE IDENTIFICAN FRACTURAS NI TUMORACIONES. | V18: TORAX RADIOLOGICAMENTE NORMAL, SIN EVIDENCIA DE PATOLOGÍA AGUDA O EVOLUTIVA APARENTE. | AO18: =AVERAGE(#REF!,#REF!) -> #REF!
A19: 168098 | B19: GOMEZ MARTINEZ CARLOS | C19: MASCULINO | D19: SOLDADURA | E19: 5 AÑOS | F19: NORMAL | G19: NORMAL | H19: NORMAL | I19: FATIGA AUDITIVA | J19: Audición Normal | K19: Audición Normal, Datos de Fatiga Auditiva | L19: 4.25 | M19: NORMAL | N19: 0.95 | O19: NEGADO | P19: Electrocardiograma en reposo sin datos de anormalidad al momento del estudio | Q19: 1.- HIPERLORDOSIS 2.- PIE PLANO | R19: 3 | S19: 44 | T19: 0 | U19: DESVIACION DEXTROCONVEXA LUMBOSACRA ( 3 ° ) CON HIPERLORDOSIS, INESTABILIDAD LUMBAR Y CON ANGULO DE 44 °. PINZAMIENTO L5-S1. NO SE IDENTIFICAN FRACTURAS NI TUMORACIONES. | V19: TORAX RADIOLOGICAMENTE NORMAL, SIN EVIDENCIA DE PATOLOGÍA AGUDA O EVOLUTIVA APARENTE. | AO19: =AVERAGE(#REF!,#REF!) -> #REF!
A20: 168040 | B20: GONZALEZ BARRERA VICTOR MANUEL | C20: MASCULINO | D20: MAQUINADOS | E20: 1 AÑO | F20: NORMAL | G20: NORMAL | H20: NORMAL | I20: FATIGA AUDITIVA | J20: Audición Normal | K20: Audición Normal, Datos de Fatiga Auditiva | L20: 3.63 | M20: PATRÓN ESPIROMÉTRICO RESTRICTIVO LEVE | N20: 0.79 | O20: NEGADO | P20: TAQUICARDIA SINUSAL, RESTO DEL ESTUDIO SIN DATOS DE ANORMALIDAD EL MOMENTO | Q20: 1.-GENUVARO. 2.- PIE PLANO 3.- ALLUX VALGUX | R20: 4 | S20: 44 | T20: 0 | U20: DESVIACION LEVOCONVEXA LUMBOSACRA ( 4 ° ) CON HIPERLORDOSIS, INESTABILIDAD LUMBAR Y CON ANGULO DE 44 °. PINZAMIENTO L5-S1. NO SE IDENTIFICAN FRACTURAS NI TUMORACIONES. | V20: TORAX RADIOLOGICAMENTE NORMAL, SIN EVIDENCIA DE PATOLOGÍA AGUDA O EVOLUTIVA APARENTE. | AO20: =AVERAGE(#REF!,#REF!) -> #REF!
A21: 168014 | B21: GONZALEZ CASAS LUIS EDUARDO | C21: MASCULINO | D21: MAQUINADOS | E21: 5 AÑOS | F21: DISMINUIDA NO CORREGIDA | G21: NORMAL | H21: NORMAL | I21: FATIGA AUDITIVA | J21: Audición Normal, Datos de Fatiga Auditiva | K21: Audición Normal, Datos de Fatiga Auditiva | L21: 5.38 | M21: NORMAL | N21: 0.91 | O21: POSITIVO | P21: Electrocardiograma en reposo sin datos de anormalidad al momento del estudio | Q21: 1.- LUMBALGIA | R21: 3 | S21: 36 | T21: 0 | U21: DESVIACION LEVOCONVEXA LUMBOSACRA ( 3 ° ) CON LORDOSIS NORMAL, Y CON ANGULO DE 36 °. BOSTEZO L5-S1. NO SE IDENTIFICAN FRACTURAS NI TUMORACIONES. | V21: TORAX RADIOLOGICAMENTE NORMAL, SIN EVIDENCIA DE PATOLOGÍA AGUDA O EVOLUTIVA APARENTE. | AO21: =AVERAGE(#REF!,#REF!) -> #REF!
A22: 168047 | B22: GONZALEZ GONDINEZ LUIS ESTEBAN | C22: MASCULINO | D22: PINTURA | E22: 2 AÑOS 7 MESES | F22: N/A | G22: N/A | H22: N/A | I22: NORMAL | J22: Audición Normal | K22: Audición Normal | L22: 2.25 | M22: N/A | N22: N/A | O22: NEGADO | P22: N/A | Q22: 1.- LORDOSIS. | R22: 4 | S22: 30 | T22: 0 | U22: DESVIACION LEVOCONVEXA LUMBOSACRA ( 4 ) CON LORDOSIS NORMAL Y CON ANGULO DE 30°. LIGERO PINZAMIENTO L5-S1. LUMBARIZACION DE S1, CON PINZAMIENTO S1-2 NO SE IDENTIFICAN FRACTURAS NI TUMORACIONES. | V22: N/A | AO22: =AVERAGE(#REF!,#REF!) -> #REF!
A23: 168056 | B23: GONZALEZ RANGEL JOSE MAXIMILIANO | C23: MASCULINO | D23: SOLDADURA | E23: 3 AÑOS 6 MESES | F23: NORMAL | G23: NORMAL | H23: NORMAL | I23: NORMAL | J23: Audición Normal | K23: Audición Normal | L23: 3.5 | M23: PATRÓN ESPIROMÉTRICO RESTRICTIVO LEVE | N23: 0.71 | O23: NEGADO | P23: Electrocardiograma en reposo sin datos de anormalidad al momento del estudio | Q23: 1.- HIPERLORDOSIS 2.- PIE PLANO | R23: 2 | S23: 34 | T23: 0 | U23: DESVIACIÓN DEXTROCONVEXA LUMBOSACRA (2º), (Angulo de Ferguson 34 º). DISMINUCION DE L5-S1.NO SE IDENTIFICAN FRACTURAS NI LISTESIS. | V23: TÓRAX RADIOLÓGICAMENTE NORMAL, SIN PATOLOGÍA AGUDA APARENTE | AO23: =AVERAGE(#REF!,#REF!) -> #REF!
A24: 168066 | B24: GONZALEZ TOMAS SILVESTRE | C24: MASCULINO | D24: PINTURA | E24: 4 AÑOS | F24: NORMAL | G24: NORMAL | H24: NORMAL | I24: LEVE TA | J24: Hipoacusia Neurosensorial, Leve , Sugestivo de Trauma Acústico crónico por ruido | K24: Audición Normal | L24: 8 | M24: PATRÓN ESPIROMÉTRICO RESTRICTIVO LEVE | N24: 0.75 | O24: NEGADO | P24: Bradicardia sinusal, resto del estudio sin datos de anormalidad al momento del estudio | Q24: 1.- LORDOSIS, 2.- PIE PLANO 3.-LIMITACION EN LATERALIZACION Y EXTENSION. | R24: 5 | S24: 45 | T24: 1 | U24: DESVIACION DEXTROCONVEXA LUMBOSACRA ( 5 ° ) CON HIPERLORDOSIS, INESTABILIDAD LUMBAR, Y CON ANGULO DE 45 °. PINZAMIENTO L5-S1. NO SE IDENTIFICAN FRACTURAS NI TUMORACIONES. BASCULACION PELVICA DERECHA DE 1.0 cm. | V24: TORAX RADIOLOGICAMENTE NORMAL, SIN EVIDENCIA DE PATOLOGÍA AGUDA O EVOLUTIVA APARENTE. | AO24: =AVERAGE(#REF!,#REF!) -> #REF!
A25: 168093 | B25: GRIJALVA HERRERA BENJAMIN | C25: MASCULINO | D25: SOLDADURA | E25: 4 AÑOS 5 MESES | F25: NORMAL | G25: NORMAL | H25: NORMAL | I25: NORMAL | J25: Audición Normal | K25: Audición Normal | L25: 0.63 | M25: NORMAL | N25: 1 | O25: POSITIVO | P25: Bradicardia sinusal, resto del estudio sin datos de anormalidad al momento del estudio | Q25: 1.- HIPERLORDOSIS. 2.- GENU - RECURVATUM. | R25: 3 | S25: 42 | T25: 0 | U25: DESVIACION DEXTROCONVEXA LUMBOSACRA ( 3 ° ) CON HIPERLORDOSIS Y CON ANGULO DE 42 °. PINZAMIENTO L5-S1. NO SE IDENTIFICAN FRACTURAS NI TUMORACIONES. | V25: TORAX RADIOLOGICAMENTE NORMAL, SIN EVIDENCIA DE PATOLOGÍA AGUDA O EVOLUTIVA APARENTE. PROBABLE GRANULOMA SUPERIOR IZQUIERDO. | AO25: =AVERAGE(#REF!,#REF!) -> #REF!
A26: 168019 | B26: GUZMAN SANABRIA CESAR | C26: MASCULINO | D26: SOLDADURA | E26: 4 AÑOS 11 MESES | F26: NORMAL | G26: NORMAL | H26: NORMAL | I26: FATIGA AUDITIVA | J26: Audición Normal | K26: Audición Normal, Datos de Fatiga Auditiva | L26: 4.63 | M26: PATRÓN ESPIROMÉTRICO RESTRICTIVO LEVE | N26: 0.71 | O26: NEGADO | P26: Electrocardiograma en reposo sin datos de anormalidad al momento del estudio | Q26: 1.- GENU VARO. 2.- ANTEPULSION DE CABEZA. 3.- ANTEVERSION DE CADERA. | R26: 5 | S26: 36 | T26: 0 | U26: DESVIACION DEXTROCONVEXA LUMBOSACRA ( 5 ° ) CON LORDOSIS NORMAL, Y CON ANGULO DE 36 °. LIGERO PINZAMIENTO L5-S1. NO SE IDENTIFICAN FRACTURAS NI TUMORACIONES. | V26: TORAX RADIOLOGICAMENTE NORMAL, SIN EVIDENCIA DE PATOLOGÍA AGUDA O EVOLUTIVA APARENTE. | AO26: =AVERAGE(#REF!,#REF!) -> #REF!
A27: 168054 | B27: HERNANDEZ BARRERA MARIA GUADALUPE | C27: FEMENINO | D27: MANTENIMIENTO | E27: 11 MESES | F27: N/A | G27: N/A | H27: N/A | I27: NORMAL | J27: Audición Normal | K27: Audición Normal | L27: 7.63 | M27: N/A | N27: N/A | O27: NEGADO | P27: N/A | Q27: 1.- HIPERLORDOSIS 2.- HIPERSIFOSIS. | R27: 4 | S27: 44 | T27: 0 | U27: DESVIACION DEXTROCONVEXA LUMBOSACRA ( 4 ) CON HIPERLORDOSIS, INESTABILIDAD LUMBAR Y CON ANGULO DE 44°. NO SE IDENTIFICAN FRACTURAS NI TUMORACIONES. | V27: N/A | AO27: =AVERAGE(#REF!,#REF!) -> #REF!
A28: 168015 | B28: HERNANDEZ DORANTES HUMBERTO | C28: MASCULINO | E28: 1 AÑO | F28: NORMAL | G28: NORMAL | H28: NORMAL | I28: NORMAL | J28: Audición Normal | K28: Audición Normal | L28: -0.63 | M28: NORMAL | N28: 0.95 | O28: NEGADO | P28: Electrocardiograma en reposo sin datos de anormalidad al momento del estudio | Q28: 1.- HIPERLORDOSIS 2.- PIE PLANO | R28: 3 | S28: 52 | T28: 0 | U28: DESVIACION LEVOCONVEXA LUMBOSACRA ( 3 ° ) CON HIPERLORDOSIS, INESTABILIDAD LUMBAR, Y CON ANGULO DE 52 °. PINZAMIENTO L5-S1. LUMBARIZACION DE S1 CON DISRAFIA Y DISPLASIA DE SU ARCO POSTERIOR NO SE IDENTIFICAN FRACTURAS NI TUMORACIONES. | V28: TORAX RADIOLOGICAMENTE NORMAL, SIN EVIDENCIA DE PATOLOGÍA AGUDA O EVOLUTIVA APARENTE. | AO28: =AVERAGE(#REF!,#REF!) -> #REF!
A29: 168139 | B29: HERNANDEZ HUERTA URIEL | C29: MASCULINO | E29: 6 MESES | F29: NORMAL | G29: NORMAL | H29: NORMAL | I29: NORMAL | J29: Audición Normal | K29: Audición Normal | L29: 4 | M29: PATRÓN ESPIROMÉTRICO RESTRICTIVO LEVE | N29: 0.74 | O29: NEGADO | P29: Electrocardiograma en reposo sin datos de anormalidad al momento del estudio | Q29: 1.- HIPERLORDOSIS LUMBAR, 2.- ANTEVERSION PELVICA, 3.- GENU RECURVATUM. | R29: 3 | S29: 40 | T29: 0 | U29: DESVIACION DEXTROCONVEXA LUMBOSACRA ( 3 ° ) CON HIPERLORDOSIS Y CON ANGULO DE 40 °. ESTRECHAMIENTO Y PINZAMIENTO L5-S1. NO SE IDENTIFICAN FRACTURAS NI TUMORACIONES. | V29: TORAX RADIOLOGICAMENTE NORMAL, SIN EVIDENCIA DE PATOLOGÍA AGUDA O EVOLUTIVA APARENTE. | AO29: =AVERAGE(#REF!,#REF!) -> #REF!
A30: 168050 | B30: HERNANDEZ PEREZ ANGEL ALBERTO | C30: MASCULINO | D30: MAQUINADOS | E30: 3 AÑOS | F30: NORMAL | G30: NORMAL | H30: NORMAL | I30: LEVE TA | J30: Hipoacusia Neurosensorial, Leve , Sugestivo de Trauma Acústico crónico por ruido | K30: Hipoacusia Neurosensorial, Profunda, De etiología a determinar | L30: 22 | M30: NORMAL | N30: 0.91 | O30: POSITIVO | P30: Electrocardiograma en reposo sin datos de anormalidad al momento del estudio | Q30: 1.- LORDOSIS 2.- HIPERCIFOSIS 3.- ANTEVERSION DE CAREDA 4 | R30: 3 | S30: 42 | T30: 0 | U30: DESVIACION DEXTROCONVEXA LUMBOSACRA ( 3 ° ) CON HIPERLORDOSIS, Y CON ANGULO DE 42 °. BOSTEZO Y LIGERO PINZAMIENTO L5-S1. NO SE IDENTIFICAN FRACTURAS NI TUMORACIONES. | V30: TORAX RADIOLOGICAMENTE NORMAL, SIN EVIDENCIA DE PATOLOGÍA AGUDA O EVOLUTIVA APARENTE. | AO30: =AVERAGE(#REF!,#REF!) -> #REF!
A31: 168154 | B31: HERNANDEZ VILLANUEVA JOSE ROBERTO | C31: MASCULINO | D31: MANTENIMIENTO | E31: 4 AÑOS 6 MESES | F31: N/A | G31: N/A | H31: N/A | I31: NO RELACIONADA A RUIDO LABORAL | J31: Hipoacusia Neurosensorial, Leve , Sugestivo a Presbiacusia | K31: Audición Normal | L31: 3.13 | M31: N/A | N31: N/A | O31: NEGADO | P31: N/A | Q31: 1.- LORDISIS . | R31: 4 | S31: 36 | T31: 0 | U31: DESVIACION DEXTROCONVEXA LUMBOSACRA ( 4 ° ) CON LORDOSIS NORMAL Y CON ANGULO DE 36 °. ESTRECHAMIENTO L5-S1. NO SE IDENTIFICAN FRACTURAS NI TUMORACIONES. | V31: N/A | AO31: =AVERAGE(#REF!,#REF!) -> #REF!
A32: 168121 | B32: IBARRA FLORES JOSE MANUEL | C32: MASCULINO | D32: MAQUINADOS | E32: 3 AÑOS | F32: DISMINUIDA CORREGIDA | G32: NORMAL | H32: NORMAL | I32: FATIGA AUDITIVA | J32: Audición Normal, Datos de Fatiga Auditiva | K32: Audición Normal, Datos de Fatiga Auditiva | L32: 2.5 | M32: NORMAL | N32: 0.91 | O32: NEGADO | P32: Bradicardia sinusal, resto del estudio sin datos de anormalidad al momento del estudio | Q32: 1.-GENU VARO, 2.- HIPERLORDOSIS | R32: 3 | S32: 30 | T32: 0 | U32: DESVIACION DEXTROCONVEXA LUMBOSACRA ( 3 ° ) CON LORDOSIS NORMAL Y CON ANGULO DE 30 °. ESTRECHAMIENTO Y PINZAMIENTO L5-S1. NO SE IDENTIFICAN FRACTURAS NI TUMORACIONES. | V32: TORAX RADIOLOGICAMENTE NORMAL, SIN EVIDENCIA DE PATOLOGÍA AGUDA O EVOLUTIVA APARENTE. | AO32: =AVERAGE(#REF!,#REF!) -> #REF!
A33: 168099 | B33: IBARRA LARA JULIO CESAR | C33: MASCULINO | D33: MAQUINADOS | E33: 4 AÑOS 5 MESES | F33: NORMAL | G33: NORMAL | H33: NORMAL | I33: NORMAL | J33: Audición Normal | K33: Audición Normal | L33: 3.13 | M33: NORMAL | N33: 0.93 | O33: NEGADO | P33: Electrocardiograma en reposo sin datos de anormalidad al momento del estudio | Q33: 1.- HIPERLORDOSIS | R33: 4 | S33: 45 | T33: 0 | U33: DESVIACION DEXTROCONVEXA LUMBOSACRA ( 4 ° ) CON HIPERLORDOSIS Y CON ANGULO DE 45 °. PINZAMIENTO L5-S1. NO SE IDENTIFICAN FRACTURAS NI TUMORACIONES. | V33: TORAX RADIOLOGICAMENTE NORMAL, SIN EVIDENCIA DE PATOLOGÍA AGUDA O EVOLUTIVA APARENTE. | AO33: =AVERAGE(#REF!,#REF!) -> #REF!
A34: 168138 | B34: JIMENEZ GONZALEZ ROBERTO | C34: MASCULINO | D34: MAQUINADOS | E34: 3 AÑOS | F34: NORMAL | G34: NORMAL | H34: NORMAL | I34: FATIGA AUDITIVA | J34: Audición Normal, Datos de Fatiga Auditiva | K34: Audición Normal, Datos de Fatiga Auditiva | L34: 1 | M34: NORMAL | N34: 0.82 | O34: POSITIVO | P34: Electrocardiograma en reposo sin datos de anormalidad al momento del estudio | Q34: 1.- HIPERLORDOSIS. | R34: 2 | S34: 40 | T34: 0 | U34: DESVIACION DEXTROCONVEXA LUMBOSACRA ( 2 ° ) CON HIPERLORDOSIS Y CON ANGULO DE 40 °. PINZAMIENTO L5-S1. NO SE IDENTIFICAN FRACTURAS NI TUMORACIONES. | V34: TORAX RADIOLOGICAMENTE NORMAL, SIN EVIDENCIA DE PATOLOGÍA AGUDA O EVOLUTIVA APARENTE. | AO34: =AVERAGE(#REF!,#REF!) -> #REF!
A35: 168150 | B35: JIMENEZ MEDINA RAMIRO | C35: MASCULINO | D35: SOLDADURA | E35: 3 AÑOS | F35: NORMAL | G35: NORMAL | H35: NORMAL | I35: FATIGA AUDITIVA | J35: Audición Normal, Datos de Fatiga Auditiva | K35: Audición Normal, Datos de Fatiga Auditiva | L35: 6.13 | M35: NORMAL | N35: 0.99 | O35: NEGADO | P35: Electrocardiograma en reposo sin datos de anormalidad al momento del estudio | Q35: 1.- HIPERLORDOSIS | R35: 4 | S35: 40 | T35: 0 | U35: DESVIACION LEVOCONVEXA LUMBOSACRA ( 4 ° ) CON HIPERLORDOSIS Y CON ANGULO DE 40 °. PINZAMIENTO L5-S1. NO SE IDENTIFICAN FRACTURAS NI TUMORACIONES. | V35: TORAX RADIOLOGICAMENTE NORMAL, SIN EVIDENCIA DE PATOLOGÍA AGUDA O EVOLUTIVA APARENTE. | AO35: =AVERAGE(#REF!,#REF!) -> #REF!
A36: 168152 | B36: LUNA RODRIGUEZ AARON | C36: MASCULINO | D36: SOLDADURA | E36: 3 AÑOS | F36: NORMAL | G36: NORMAL | H36: NORMAL | I36: LEVE TA | J36: Audición Normal | K36: Hipoacusia Neurosensorial, Leve, Sugestivo de Trauma Acústico crónico por ruido | L36: 6.63 | M36: PATRÓN ESPIROMÉTRICO RESTRICTIVO LEVE | N36: 0.71 | O36: NEGADO | P36: Bradicardia sinusal, resto del estudio sin datos de anormalidad al momento del estudio | Q36: 1,-ALINEACION POSTURAL NORMAL | R36: 7 | S36: 38 | T36: 2 | U36: DESVIACION DEXTROCONVEXA LUMBOSACRA ( 7 ° ) CON LORDOSIS NORMAL Y CON ANGULO DE 38 °. ESTRECHAMIENTO L5-S1 Y OSTEOFITOSIS. NO SE IDENTIFICAN FRACTURAS NI TUMORACIONES. BASCULACION PELVICA DERECHA DE 2.0 cm | V36: TORAX RADIOLOGICAMENTE NORMAL, SIN EVIDENCIA DE PATOLOGÍA AGUDA O EVOLUTIVA APARENTE. | AO36: =AVERAGE(#REF!,#REF!) -> #REF!
A37: 168045 | B37: MARTINEZ GARCIA LUIS ANGEL | C37: MASCULINO | D37: ALMACEN F5 | E37: 3 AÑOS 1 MES | F37: DISMINUIDA CORREGIDA | G37: NORMAL | H37: NORMAL | I37: FATIGA AUDITIVA | J37: Audición Normal, Datos de Fatiga Auditiva | K37: Audición Normal | L37: 1 | M37: NORMAL | N37: 0.95 | O37: NEGADO | P37: Electrocardiograma en reposo sin datos de anormalidad al momento del estudio | Q37: 1.- HIPERCIFOSIS CERVICAL. 2.- HIPERLORDOSIS LUMBAR. 3.- PIE PLANO. 4.- ESCAPULAS ALADAS. 5.- CABEZA LATERALIZADA A LA DERECHA Y CON INCLINACION ANTERIOR. 6.- HOMBRO DERECHO CON ASCENSO | R37: 4 | S37: 34 | T37: 0 | U37: DESVIACION LEVOCONVEXA LUMBOSACRA ( 4 ° ) CON LORDOSIS NORMAL, Y CON ANGULO DE 34 °. LIGERO PINZAMIENTO L5-S1. NO SE IDENTIFICAN FRACTURAS NI TUMORACIONES. | V37: TORAX RADIOLOGICAMENTE NORMAL, SIN EVIDENCIA DE PATOLOGÍA AGUDA O EVOLUTIVA APARENTE. | AO37: =AVERAGE(#REF!,#REF!) -> #REF!
A38: 168116 | B38: MARTINEZ PEREZ ANTONIO | C38: MASCULINO | D38: MAQUINADOS | E38: 2 AÑOS 6 MESES | F38: DISMINUIDA SIN USO DE LENTES | G38: NORMAL | H38: DISCROMATOPSIA | I38: NORMAL | J38: Audición Normal | K38: Audición Normal | L38: 9.13 | M38: PATRÓN ESPIROMÉTRICO RESTRICTIVO LEVE | N38: 0.7 | O38: NEGADO | P38: Electrocardiograma en reposo sin datos de anormalidad al momento del estudio | Q38: 1.- ESCOLIOSIS, 2.- HIPERLORDOSIS LUMBAR | R38: 5 | S38: 40 | T38: 1 | U38: DESVIACION LEVOCONVEXA LUMBOSACRA ( 5 ° ) CON HIPERLORDOSIS Y CON ANGULO DE 40 °. PINZAMIENTO L5-S1 Y OSTEOFITOSIS. NO SE IDENTIFICAN FRACTURAS NI TUMORACIONES. BASCULACION PELVICA IZQUIERDA DE 1.0 cm | V38: TORAX RADIOLOGICAMENTE NORMAL, SIN EVIDENCIA DE PATOLOGÍA AGUDA O EVOLUTIVA APARENTE. | AO38: =AVERAGE(#REF!,#REF!) -> #REF!
A39: 168137 | B39: MEDINA RODRIGUEZ MARTIN | C39: MASCULINO | D39: MAQUINADOS | E39: 3 AÑOS | F39: DISMINUIDA SIN USO DE LENTES | G39: NORMAL | H39: NORMAL | I39: NORMAL | J39: Audición Normal | K39: Audición Normal | L39: 2.5 | M39: NORMAL | N39: 0.92 | O39: POSITIVO | P39: Electrocardiograma en reposo sin datos de anormalidad al momento del estudio | Q39: 1.- HIPERLORDOSIS | R39: 3 | S39: 42 | T39: 0 | U39: DESVIACION DEXTROCONVEXA LUMBOSACRA ( 3 ° ) CON HIPERLORDOSIS Y CON ANGULO DE 42 °. ESTRECHAMIENTO Y PINZAMIENTO L5-S1. NO SE IDENTIFICAN FRACTURAS NI TUMORACIONES. | V39: TORAX RADIOLOGICAMENTE NORMAL, SIN EVIDENCIA DE PATOLOGÍA AGUDA O EVOLUTIVA APARENTE. | AO39: =AVERAGE(#REF!,#REF!) -> #REF!
A40: 168051 | B40: MEJIA HERNANDEZ JESUS DANIEL | C40: MASCULINO | D40: MAQUINADOS | E40: 3 AÑOS | F40: DISMINUIDA NO CORREGIDA | G40: NORMAL | H40: NORMAL | I40: NORMAL | J40: Audición Normal | K40: Audición Normal | L40: 3.25 | M40: NORMAL | N40: 1.04 | O40: POSITIVO | P40: Electrocardiograma en reposo sin datos de anormalidad al momento del estudio | Q40: 1.- GENUVALGO | R40: 4 | S40: 40 | T40: 0 | U40: DESVIACION DEXTROCONVEXA LUMBOSACRA ( 4 ° ) CON HIPERLORDOSIS, Y CON ANGULO DE 40 °. LIGERO PINZAMIENTO L5-S1. NO SE IDENTIFICAN FRACTURAS NI TUMORACIONES. | V40: TORAX RADIOLOGICAMENTE NORMAL, SIN EVIDENCIA DE PATOLOGÍA AGUDA O EVOLUTIVA APARENTE. | AO40: =AVERAGE(#REF!,#REF!) -> #REF!
...

Sheet LABORATORIOS
A1: BITACORA DE RESULTADOS
E2: BIOMETRIA HEMATICA | J2: QUIMICA SANGUINEA 6 | Q2: EXAMEN GENERAL DE ORINA | V2: TOXICOLOGICO
A3: Folio | B3: Nombre | C3: SEXO | D3: Edad | E3: BH Hb | F3: BH MCHb | G3: BH CHGM | H3: BH LEU | I3: BH PLA | J3: GLUC | K3: BUN-LAB | L3: UREA | M3: CREAT | N3: AU | O3: COL | P3: TRIG | Q3: EGO-GLC | R3: EGO-PROT | S3: EGOblo | T3: EGO BAC | U3: CRISTALES EGO | V3: ANFETA | W3: COCA | X3: MARIHUA | Y3: OPIAC | Z3: METANF
A4: 260417010016 | B4: AGUILAR ARREOLA JOSE DAVID | C4: MASCULINO | D4: 28 A | E4: 16.4 | F4: 31.2 | G4: 34.1 | H4: 7.6 | I4: 217 | J4: 74.3 | K4: 17 | L4: 36.3 | M4: 1 | N4: 9.8 | O4: 208.8 | P4: 80.3 | Q4: 0 | R4: 0 | S4: 0 | T4: AUSENTES | U4: URATOS AMORFOS ESCASOS | V4: POSITIVO | W4: NEGATIVO | X4: NEGATIVO | Y4: NEGATIVO | Z4: POSITIVO
A5: 260417010017 | B5: ALDABALDE MARTINEZ SAUL | C5: MASCULINO | D5: 44 A | E5: 16.4 | F5: 31.2 | G5: 34.2 | H5: 7.7 | I5: 312 | J5: 82.6 | K5: 13.9 | L5: 29.7 | M5: 0.9 | N5: 7.7 | O5: 212.6 | P5: 166.2 | Q5: 0 | R5: 0 | S5: 0 | T5: AUSENTES | U5: AUSENTES | V5: NEGATIVO | W5: NEGATIVO | X5: NEGATIVO | Y5: NEGATIVO | Z5: NEGATIVO
A6: 260417010018 | B6: ARREDONDO ORTIZ VICTOR HUGO | C6: MASCULINO | D6: 38 A | E6: 16.7 | F6: 29.2 | G6: 34 | H6: 5.8 | I6: 173 | J6: 78.6 | K6: 15.2 | L6: 32.5 | M6: 1 | N6: 6.6 | O6: 164.3 | P6: 210 | Q6: 0 | R6: 0 | S6: 0 | T6: ESCASAS | U6: URATOS AMORFOS ESCASOS | V6: NEGATIVO | W6: NEGATIVO | X6: NEGATIVO | Y6: NEGATIVO | Z6: NEGATIVO
A7: 260417010019 | B7: GARCIA PACHUCA LUIS FERNANDO | C7: MASCULINO | D7: 21 A | E7: 16.4 | F7: 28 | G7: 34 | H7: 5.8 | I7: 226 | J7: 64.1 | K7: 17.1 | L7: 36.5 | M7: 1.1 | N7: 7.1 | O7: 148 | P7: 112.4 | Q7: 0 | R7: 0 | S7: 0 | T7: ESCASAS | U7: URATOS AMORFOS ESCASOS | V7: NEGATIVO | W7: NEGATIVO | X7: NEGATIVO | Y7: NEGATIVO | Z7: NEGATIVO
A8: 260417010020 | B8: GOMEZ LUCIO JOSE MANUEL | C8: MASCULINO | D8: 30 A | E8: 17.3 | F8: 31.2 | G8: 33.9 | H8: 6.2 | I8: 251 | J8: 69.3 | K8: 13.7 | L8: 29.3 | M8: 1.3 | N8: 7.5 | O8: 196.1 | P8: 225.2 | Q8: 0 | R8: 0 | S8: 0 | T8: ESCASAS | U8: URATOS AMORFOS MODERADOS | V8: NEGATIVO | W8: NEGATIVO | X8: NEGATIVO | Y8: NEGATIVO | Z8: NEGATIVO
A9: 260417010021 | B9: GONZALEZ BARRERA VICTOR MANUEL | C9: MASCULINO | D9: 36 A | E9: 15.3 | F9: 27.4 | G9: 33.5 | H9: 5.4 | I9: 276 | J9: 84.5 | K9: 20.7 | L9: 44.4 | M9: 0.8 | N9: 7 | O9: 188.6 | P9: 128.3 | Q9: 0 | R9: 0 | S9: 0 | T9: ESCASAS | U9: URATOS AMORFOS ESCASOS | V9: NEGATIVO | W9: NEGATIVO | X9: NEGATIVO | Y9: NEGATIVO | Z9: NEGATIVO
A10: 260417010022 | B10: GONZALEZ CASAS LUIS EDUARDO | C10: MASCULINO | D10: 27 A | E10: 16.6 | F10: 30 | G10: 34.3 | H10: 8.6 | I10: 339 | J10: 67.2 | K10: 11.6 | L10: 24.8 | M10: 0.9 | N10: 5.8 | O10: 140.6 | P10: 75.7 | Q10: 0 | R10: 0 | S10: 0 | T10: ESCASAS | U10: FOSFATOS AMORFOS ABUNDANTES | V10: NEGATIVO | W10: NEGATIVO | X10: NEGATIVO | Y10: NEGATIVO | Z10: NEGATIVO
A11: 260417010023 | B11: GONZALEZ RANGEL JOSE MAXIMILIANO | C11: MASCULINO | D11: 33 A | E11: 16.4 | F11: 29.8 | G11: 34.5 | H11: 6.8 | I11: 203 | J11: 70.4 | K11: 16.5 | L11: 35.3 | M11: 1 | N11: 6 | O11: 145.6 | P11: 151.2 | Q11: 0 | R11: 0 | S11: 0 | T11: ESCASAS | U11: FOSFATOS AMORFOS ABUNDANTES | V11: NEGATIVO | W11: NEGATIVO | X11: NEGATIVO | Y11: NEGATIVO | Z11: NEGATIVO
A12: 260417010024 | B12: GONZALEZ TOMAS SILVESTRE | C12: MASCULINO | D12: 42 A | E12: 14.9 | F12: 30 | G12: 34.4 | H12: 5.6 | I12: 276 | J12: 89 | K12: 17.9 | L12: 38.2 | M12: 1.2 | N12: 6.2 | O12: 146.4 | P12: 177.2 | Q12: 0 | R12: 0 | S12: 0 | T12: ESCASAS | U12: URATOS AMORFOS ESCASOS | V12: NEGATIVO | W12: NEGATIVO | X12: NEGATIVO | Y12: NEGATIVO | Z12: NEGATIVO
A13: 260417010025 | B13: GUZMAN SANABRIA CESAR | C13: MASCULINO | D13: 45 A | E13: 17 | F13: 31.3 | G13: 35 | H13: 8 | I13: 220 | J13: 81.9 | K13: 14.8 | L13: 31.7 | M13: 1 | N13: 5.8 | O13: 177.2 | P13: 217.6 | Q13: 0 | R13: 0 | S13: 0 | T13: ESCASAS | U13: URATOS AMORFOS ESCASOS | V13: NEGATIVO | W13: NEGATIVO | X13: NEGATIVO | Y13: NEGATIVO | Z13: NEGATIVO
A14: 260417010026 | B14: HERNANDEZ BARRERA MARIA GUADALUPE | C14: FEMENINO | D14: 28 A | E14: 14.6 | F14: 33.2 | G14: 34.5 | H14: 7.1 | I14: 271 | J14: 74.8 | K14: 9.5 | L14: 20.3 | M14: 0.6 | N14: 5.6 | O14: 116.1 | P14: 60.6 | Q14: 0 | R14: 0 | S14: 0 | T14: AUSENTES | U14: URATOS AMORFOS ESCASOS | V14: NEGATIVO | W14: NEGATIVO | X14: NEGATIVO | Y14: NEGATIVO | Z14: NEGATIVO
A15: 260417010027 | B15: HERNANDEZ PEREZ ANGEL ALBERTO | C15: MASCULINO | D15: 33 A | E15: 14.7 | F15: 27.7 | G15: 32.8 | H15: 7.4 | I15: 215 | J15: 80 | K15: 16.3 | L15: 34.8 | M15: 1 | N15: 5.3 | O15: 164.2 | P15: 65.3 | Q15: 0 | R15: 0 | S15: 0 | T15: ESCASAS | U15: AUSENTES | V15: NEGATIVO | W15: NEGATIVO | X15: NEGATIVO | Y15: NEGATIVO | Z15: NEGATIVO
A16: 260417010028 | B16: MARTINEZ GARCIA LUIS ANGEL | C16: MASCULINO | D16: 28 A | E16: 13.9 | F16: 30.5 | G16: 34.2 | H16: 7.3 | I16: 192 | J16: 83 | K16: 18.3 | L16: 39.3 | M16: 1.1 | N16: 6.4 | O16: 153.9 | P16: 92.7 | Q16: 0 | R16: 0 | S16: 0 | T16: ESCASAS | U16: AUSENTES | V16: NEGATIVO | W16: NEGATIVO | X16: NEGATIVO | Y16: NEGATIVO | Z16: NEGATIVO
A17: 260417010029 | B17: MEJIA HERNANDEZ JESUS DANIEL | C17: MASCULINO | D17: 30 A | E17: 17.1 | F17: 32.8 | G17: 35 | H17: 6.6 | I17: 193 | J17: 84.3 | K17: 17.6 | L17: 37.7 | M17: 1 | N17: 7.3 | O17: 200.9 | P17: 117 | Q17: 0 | R17: 0 | S17: 0 | T17: ESCASAS | U17: AUSENTES | V17: NEGATIVO | W17: NEGATIVO | X17: NEGATIVO | Y17: NEGATIVO | Z17: NEGATIVO
A18: 260417010030 | B18: MIRANDA CUEVAS HUGO | C18: MASCULINO | D18: 45 A | E18: 17.2 | F18: 31.4 | G18: 34.7 | H18: 4.9 | I18: 251 | J18: 85.2 | K18: 11.4 | L18: 24.3 | M18: 0.9 | N18: 7.5 | O18: 164.1 | P18: 208.5 | Q18: 0 | R18: 0 | S18: 0 | T18: ESCASAS | U18: AUSENTES | V18: NEGATIVO | W18: NEGATIVO | X18: NEGATIVO | Y18: NEGATIVO | Z18: NEGATIVO
A19: 260417010031 | B19: MORENO RESENDIZ MARCELO | C19: MASCULINO | D19: 44 A | E19: 16.8 | F19: 30.2 | G19: 34.9 | H19: 7.3 | I19: 366 | J19: 77.4 | K19: 16 | L19: 34.3 | M19: 1.1 | N19: 8.6 | O19: 229.3 | P19: 202.5 | Q19: 0 | R19: 0 | S19: 0 | T19: ESCASAS | U19: AUSENTES | V19: NEGATIVO | W19: NEGATIVO | X19: NEGATIVO | Y19: NEGATIVO | Z19: NEGATIVO
A20: 260417010032 | B20: NIEVES TREJO ADRIAN | C20: MASCULINO | D20: 43 A | E20: 16.2 | F20: 30.1 | G20: 34.6 | H20: 7.7 | I20: 216 | J20: 82.6 | K20: 17.7 | L20: 37.9 | M20: 1 | N20: 8 | O20: 196.6 | P20: 253.1 | Q20: 0 | R20: 0 | S20: 0 | T20: ESCASAS | U20: URATOS AMORFOS ESCASOS | V20: NEGATIVO | W20: NEGATIVO | X20: NEGATIVO | Y20: NEGATIVO | Z20: NEGATIVO
A21: 260417010033 | B21: OLVERA NIETO RODOLFO | C21: MASCULINO | D21: 32 A | E21: 17.7 | F21: 30.2 | G21: 35.1 | H21: 6.9 | I21: 350 | J21: 74.9 | K21: 20.4 | L21: 43.6 | M21: 1.2 | N21: 7.7 | O21: 183.3 | P21: 129 | Q21: 0 | R21: 0 | S21: 0 | T21: ESCASAS | U21: URATOS AMORFOS MODERADOS | V21: NEGATIVO | W21: NEGATIVO | X21: NEGATIVO | Y21: NEGATIVO | Z21: NEGATIVO
A22: 260417010034 | B22: PAREDES TLANEPANTLA PASCUAL | C22: MASCULINO | D22: 29 A | E22: 15.9 | F22: 29.3 | G22: 34.8 | H22: 5.1 | I22: 295 | J22: 79.4 | K22: 21.6 | L22: 48.2 | M22: 0.8 | N22: 4.3 | O22: 175.4 | P22: 79.7 | Q22: 0 | R22: 0 | S22: 0 | T22: ESCASAS | U22: AUSENTES | V22: NEGATIVO | W22: NEGATIVO | X22: NEGATIVO | Y22: NEGATIVO | Z22: NEGATIVO
A23: 260417010035 | B23: PEREZ GARCIA LUIS ANGEL | C23: MASCULINO | D23: 26 A | E23: 15.7 | F23: 31 | G23: 34.8 | H23: 3.7 | I23: 145 | J23: 78.2 | K23: 12.2 | L23: 26.1 | M23: 1 | N23: 6.6 | O23: 155 | P23: 81.6 | Q23: 0 | R23: 0 | S23: 0 | T23: ESCASAS | U23: URATOS AMORFOS ESCASOS | V23: NEGATIVO | W23: NEGATIVO | X23: NEGATIVO | Y23: NEGATIVO | Z23: NEGATIVO
A24: 260417010036 | B24: PEREZ NIEVES JUAN ANTONIO | C24: MASCULINO | D24: 37 A | E24: 15.4 | F24: 29.1 | G24: 35 | H24: 5.1 | I24: 248 | J24: 66.3 | K24: 23 | L24: 49.2 | M24: 1.0 | N24: 6 | O24: 181 | P24: 161.2 | Q24: 0 | R24: 0 | S24: 0 | T24: ESCASAS | U24: AUSENTES | V24: NEGATIVO | W24: NEGATIVO | X24: NEGATIVO | Y24: NEGATIVO | Z24: NEGATIVO
A25: 260417010037 | B25: RODRIGUEZ RAMIREZ VICTOR MANUEL | C25: MASCULINO | D25: 44 A | E25: 16.8 | F25: 33.2 | G25: 34.4 | H25: 5.7 | I25: 157 | J25: 89.2 | K25: 10.7 | L25: 22.8 | M25: 0.8 | N25: 6.8 | O25: 169.1 | P25: 82.1 | Q25: 0 | R25: 0 | S25: 0 | T25: ESCASAS | U25: FOSFATOS AMORFOS ESCASOS | V25: NEGATIVO | W25: NEGATIVO | X25: NEGATIVO | Y25: NEGATIVO | Z25: NEGATIVO
A26: 260417010038 | B26: TOLEDO CHAVEZ ALEJANDRO DAVID | C26: MASCULINO | D26: 35 A | E26: 16.7 | F26: 31.3 | G26: 34.7 | H26: 5.8 | I26: 284 | J26: 86.4 | K26: 15.1 | L26: 32.3 | M26: 0.9 | N26: 4 | O26: 169.2 | P26: 97 | Q26: 0 | R26: 0 | S26: 10 | T26: ESCASAS | U26: URATOS AMORFOS ESCASOS | V26: NEGATIVO | W26: NEGATIVO | X26: NEGATIVO | Y26: NEGATIVO | Z26: NEGATIVO
A27: 260417010039 | B27: TREJO DON HECTOR MIGUEL | C27: MASCULINO | D27: 39 A | E27: 16.5 | F27: 30.6 | G27: 34.1 | H27: 6.6 | I27: 162 | J27: 78.7 | K27: 18 | L27: 38.5 | M27: 1 | N27: 6.9 | O27: 238.7 | P27: 134 | Q27: 0 | R27: 0 | S27: 10 | T27: ESCASAS | U27: AUSENTES | V27: NEGATIVO | W27: NEGATIVO | X27: NEGATIVO | Y27: NEGATIVO | Z27: NEGATIVO
A28: 260417010040 | B28: TREJO LOPEZ JOSE GUADALUPE | C28: MASCULINO | D28: 26 A | E28: 15.2 | F28: 30.9 | G28: 34.3 | H28: 4.6 | I28: 187 | J28: 78.3 | K28: 10.1 | L28: 21.6 | M28: 0.9 | N28: 4.5 | O28: 161.9 | P28: 56.1 | Q28: 0 | R28: 0 | S28: 0 | T28: ESCASAS | U28: AUSENTES | V28: NEGATIVO | W28: NEGATIVO | X28: NEGATIVO | Y28: NEGATIVO | Z28: NEGATIVO
A29: 260417010041 | B29: VELAZQUEZ MORENO LORENZO | C29: MASCULINO | D29: 41 A | E29: 17.8 | F29: 30.3 | G29: 34.6 | H29: 5.5 | I29: 165 | J29: 83.8 | K29: 16.6 | L29: 35.4 | M29: 0.9 | N29: 5.6 | O29: 149 | P29: 543.6 | Q29: 0 | R29: 0 | S29: 0 | T29: ESCASAS | U29: URATOS AMORFOS ESCASOS | V29: NEGATIVO | W29: NEGATIVO | X29: NEGATIVO | Y29: NEGATIVO | Z29: NEGATIVO
A30: 260417010042 | B30: ZAMORA NOGUEZ YONATAN | C30: MASCULINO | D30: 28 A | E30: 15.6 | F30: 29.8 | G30: 34.7 | H30: 6.1 | I30: 331 | J30: 77.4 | K30: 16.2 | L30: 34.6 | M30: 1.2 | N30: 7.7 | O30: 146.3 | P30: 161.2 | Q30: 0 | R30: 0 | S30: 0 | T30: ESCASAS | U30: AUSENTES | V30: NEGATIVO | W30: NEGATIVO | X30: NEGATIVO | Y30: NEGATIVO | Z30: NEGATIVO
A31: 260417010043 | B31: GONZALEZ GODINEZ LUIS ESTEBAN | C31: MASCULINO | D31: 27 A | E31: 15.6 | F31: 31.3 | G31: 34.6 | H31: 6.4 | I31: 243 | J31: 69.8 | K31: 12.2 | L31: 26.1 | M31: 0.9 | N31: 6.1 | O31: 144.9 | P31: 52.5 | Q31: 0 | R31: 0 | S31: 0 | T31: ESCASAS | U31: URATOS AMORFOS ABUNDANTES | V31: NEGATIVO | W31: NEGATIVO | X31: NEGATIVO | Y31: NEGATIVO | Z31: NEGATIVO
A32: 260417010044 | B32: RAMIREZ DE SANTIAGO IVAN ALEJANDRO | C32: MASCULINO | D32: 44 A | E32: 16.8 | F32: 32.8 | G32: 35.9 | H32: 5.4 | I32: 222 | J32: 125.8 | K32: 10.4 | L32: 22.3 | M32: 0.8 | N32: 5.6 | O32: 164.9 | P32: 102.5 | Q32: 0 | R32: 0 | S32: 0 | T32: ESCASAS | U32: URATOS AMORFOS MODERADOS | V32: NEGATIVO | W32: NEGATIVO | X32: NEGATIVO | Y32: NEGATIVO | Z32: NEGATIVO
A33: 260417010045 | B33: HERNANDEZ DORANTES HUMBERTO | C33: MASCULINO | D33: 22 A | E33: 16.5 | F33: 30.1 | G33: 34.8 | H33: 10.4 | I33: 329 | J33: 82.7 | K33: 11.4 | L33: 24.5 | M33: 0.8 | N33: 6 | O33: 165.1 | P33: 66.6 | Q33: 0 | R33: 0 | S33: 0 | T33: ESCASAS | U33: URATOS AMORFOS ESCASOS | V33: NEGATIVO | W33: NEGATIVO | X33: NEGATIVO | Y33: NEGATIVO | Z33: NEGATIVO
A34: 260417010046 | B34: RAMIREZ PEREZ ELISABET | C34: FEMENINO | D34: 36 A | E34: 13.2 | F34: 28.3 | G34: 33.5 | H34: 9.4 | I34: 285 | J34: 74.6 | K34: 10.2 | L34: 21.8 | M34: 0.7 | N34: 4.8 | O34: 191.1 | P34: 99.5 | Q34: 0 | R34: 0 | S34: 0 | T34: MODERADAS | U34: URATOS AMORFOS ESCASOS | V34: NEGATIVO | W34: NEGATIVO | X34: NEGATIVO | Y34: NEGATIVO | Z34: NEGATIVO
A35: 260420010008 | B35: ANGEL MATA JOHAN EDGAR | C35: MASCULINO | D35: 28 A | E35: 15.9 | F35: 31 | G35: 35 | H35: 6.7 | I35: 369 | J35: 75.9 | K35: 8 | L35: 17.2 | M35: 1 | N35: 8 | O35: 144.7 | P35: 142.1 | Q35: 0 | R35: 0 | S35: 0 | T35: ESCASAS | U35: URATOS AMORFOS ESCASOS | V35: NEGATIVO | W35: NEGATIVO | X35: NEGATIVO | Y35: NEGATIVO | Z35: NEGATIVO
A36: 260420010009 | B36: BOLAÑOS PALACIOS MIREYA | C36: FEMENINO | D36: 42 A | E36: 13 | F36: 27.6 | G36: 33.4 | H36: 6.1 | I36: 342 | J36: 92.6 | K36: 11.2 | L36: 24 | M36: 0.8 | N36: 3.9 | O36: 160.3 | P36: 129.2 | Q36: 0 | R36: 0 | S36: 25 | T36: ESCASAS | U36: URATOS AMORFOS ESCASOS | V36: NEGATIVO | W36: NEGATIVO | X36: NEGATIVO | Y36: NEGATIVO | Z36: NEGATIVO
A37: 260420010010 | B37: CANO NAVA HUMBERTO | C37: MASCULINO | D37: 44 A | E37: 16.3 | F37: 30.6 | G37: 35.3 | H37: 6.7 | I37: 297 | J37: 78.2 | K37: 19.3 | L37: 41.3 | M37: 1.3 | N37: 4.3 | O37: 157.5 | P37: 109.3 | Q37: 0 | R37: 0 | S37: 0 | T37: ESCASAS | U37: AUSENTES | V37: NEGATIVO | W37: NEGATIVO | X37: NEGATIVO | Y37: NEGATIVO | Z37: NEGATIVO
A38: 260420010011 | B38: CORDOBA BANDA MARIO FERNANDO | C38: MASCULINO | D38: 29 A | E38: 15.5 | F38: 29.4 | G38: 34.4 | H38: 7 | I38: 386 | J38: 85.1 | K38: 13.6 | L38: 29.2 | M38: 1 | N38: 6.3 | O38: 164.5 | P38: 158.5 | Q38: 0 | R38: 0 | S38: 0 | T38: ESCASAS | U38: URATOS AMORFOS ESCASOS | V38: NEGATIVO | W38: NEGATIVO | X38: NEGATIVO | Y38: NEGATIVO | Z38: NEGATIVO
A39: 260420010012 | B39: CORREA CRUZ HUGO ABISAI | C39: MASCULINO | D39: 37 A | E39: 17.7 | F39: 31 | G39: 34.3 | H39: 7.2 | I39: 278 | J39: 83.3 | K39: 9.9 | L39: 21.2 | M39: 1.1 | N39: 7.1 | O39: 198.3 | P39: 249.8 | Q39: 0 | R39: 0 | S39: 0 | T39: ESCASAS | U39: OXALATOS DE CALCIO DIHIDRATADOS ESCASOS | V39: NEGATIVO | W39: NEGATIVO | X39: NEGATIVO | Y39: NEGATIVO | Z39: NEGATIVO
A40: 260420010013 | B40: DE LA CRUZ PEREZ JUAN CARLOS | C40: MASCULINO | D40: 49 A | E40: 16.7 | F40: 29.4 | G40: 34.3 | H40: 6 | I40: 194 | J40: 80.3 | K40: 15.1 | L40: 32.4 | M40: 0.8 | N40: 6.4 | O40: 143.7 | P40: 285.9 | Q40: 0 | R40: 0 | S40: 0 | T40: ESCASAS | U40: AUSENTES | V40: NEGATIVO | W40: NEGATIVO | X40: NEGATIVO | Y40: NEGATIVO | Z40: NEGATIVO
...

Sheet GRAFICAS
A2: TRAUMA ACUSTICO POR AREA | Y2: COLUMNA | AU2: QS6
A3: AREA | B3: LEVE | C3: MODERADO | D3: MODERADAMENTE GRAVE | Y3: ESCOLIOSIS | AK3: GLUCOSA | AU3: GLUCOSA
A4: LOGISTICA | B4: 1 | M4: AUDIOMETRÍAS | Y4: ='GRAFICAS OCULTAR'!O2 -> NORMAL | Z4: ='GRAFICAS OCULTAR'!P2 -> 0 | AK4: Normal | AL4: 66 | AU4: ='GRAFICAS OCULTAR'!AD3 -> Baja | AV4: ='GRAFICAS OCULTAR'!AE3 -> 0
A5: MANTENIMIENTO | B5: 1 | N5: %HBC | Y5: ='GRAFICAS OCULTAR'!O3 -> ESCOLIOSIS LEVE | Z5: ='GRAFICAS OCULTAR'!P3 -> 61 | AK5: Alto | AL5: 2 | AU5: ='GRAFICAS OCULTAR'!AD4 -> Normal | AV5: ='GRAFICAS OCULTAR'!AE4 -> 66
A6: SOLDADURA | B6: 6 | C6: 2 | M6: Muy Alto >20% | N6: ='GRAFICAS OCULTAR'!D62 -> 1 | Y6: ='GRAFICAS OCULTAR'!O4 -> ESCOLIOSIS MODERADA | Z6: ='GRAFICAS OCULTAR'!P4 -> 7 | AK6: Total | AL6: =SUM(AL3:AL5) -> 68 | AU6: ='GRAFICAS OCULTAR'!AD5 -> Alterada | AV6: ='GRAFICAS OCULTAR'!AE5 -> 1
A7: MAQUINADOS | B7: 1 | M7: Alto 10-19.9% | N7: ='GRAFICAS OCULTAR'!D61 -> 1 | Y7: ='GRAFICAS OCULTAR'!O5 -> ESCOLIOSIS GRAVE | Z7: ='GRAFICAS OCULTAR'!P5 -> 0 | AU7: ='GRAFICAS OCULTAR'!AD6 -> PB diabetes | AV7: ='GRAFICAS OCULTAR'!AE6 -> 1
A8: ALMACEN F5 | B8: 1 | M8: Bajo 0-9.9% | N8: ='GRAFICAS OCULTAR'!D60 -> 66 | AU8: ='GRAFICAS OCULTAR'!AD7 -> Etiquetas de fila | AV8: ='GRAFICAS OCULTAR'!AE7 -> Cuenta de GLUC
A9: PINTURA | B9: 2 | M9: Total | N9: =SUM(N6:N8) -> 68 | AK9: EGO
AK10: PROTEINA
AK11: Normal | AL11: 54
AK12: Alto | AL12: 4
A13: TRAUMA ACUSTICO | AK13: Total | AL13: =SUM(AL10:AL12) -> 58
A14: ANTIGÜEDAD | AU14: QS6
A15: <1 AÑO | B15: 1 | AU15: COLESTEROL
A16: 1-5 AÑOS | B16: 12 | M16: ESPIROMETRIAS | Y16: COLUMNA | AK16: EGO | AU16: ='GRAFICAS OCULTAR'!AG3 -> Normal | AV16: ='GRAFICAS OCULTAR'!AH3 -> 56
A17: 10-20 AÑOS | B17: 1 | Y17: LORDOSIS | AK17: SANGRE | AU17: ='GRAFICAS OCULTAR'!AG4 -> Moderado | AV17: ='GRAFICAS OCULTAR'!AH4 -> 10
M18: PATRÓN ESPIROMÉTRICO NO DIAGNOSTICABLES | Y18: ='GRAFICAS OCULTAR'!R2 -> DISMINUIDA | Z18: ='GRAFICAS OCULTAR'!S2 -> 0 | AK18: Normal | AL18: 62 | AU18: ='GRAFICAS OCULTAR'!AG5 -> Alto | AV18: ='GRAFICAS OCULTAR'!AH5 -> 2
M19: PATRÓN ESPIROMÉTRICO OBSTRUCTIVO | N19: 1 | Y19: ='GRAFICAS OCULTAR'!R3 -> NORMAL | Z19: ='GRAFICAS OCULTAR'!S3 -> 29 | AK19: Alto | AL19: 6 | AU19: ='GRAFICAS OCULTAR'!AG6 -> 0 | AV19: ='GRAFICAS OCULTAR'!AH6 -> 0
M20: PATRÓN ESPIROMÉTRICO RESTRICTIVO LEVE | N20: 17 | Y20: ='GRAFICAS OCULTAR'!R4 -> AUMENTADA | Z20: ='GRAFICAS OCULTAR'!S4 -> 36 | AK20: Total | AL20: =SUM(AL18:AL19) -> 68
M21: NORMAL | N21: 42 | Y21: ='GRAFICAS OCULTAR'!R5 -> HIPERLORDOSIS | Z21: ='GRAFICAS OCULTAR'!S5 -> 3
M22: TOTAL | N22: =SUM(N16:N21) -> 60
AK23: EGO
AK24: CRISTALES
AK25: SIN CRISTALES | AL25: ='GRAFICAS OCULTAR'!AQ2 -> 17
AK26: PRESENCIA DE CRISTALES | AL26: ='GRAFICAS OCULTAR'!AQ3 -> 51
Y27: COLUMNA | AK27: Total | AL27: =SUM(AL25:AL26) -> 68 | AU27: QS6
Y28: BASCULACION PELVICA | AU28: TRIGLICERIDOS
Y29: ='GRAFICAS OCULTAR'!U2 -> NORMAL | Z29: ='GRAFICAS OCULTAR'!V2 -> 61
Y30: ='GRAFICAS OCULTAR'!U3 -> LEVE | Z30: ='GRAFICAS OCULTAR'!V3 -> 7 | AK30: EGO | AU30: ='GRAFICAS OCULTAR'!AJ2 -> Baja | AV30: ='GRAFICAS OCULTAR'!AK2 -> 0
Y31: ='GRAFICAS OCULTAR'!U4 -> ALTA | Z31: ='GRAFICAS OCULTAR'!V4 -> 0 | AK31: BACTERIAS | AU31: ='GRAFICAS OCULTAR'!AJ3 -> Normal | AV31: ='GRAFICAS OCULTAR'!AK3 -> 38
AK32: ='GRAFICAS OCULTAR'!AS2 -> AUSENTES/ESCASAS | AL32: ='GRAFICAS OCULTAR'!AT2 -> 67 | AU32: ='GRAFICAS OCULTAR'!AJ4 -> Limite Alto | AV32: ='GRAFICAS OCULTAR'!AK4 -> 8
A33: ESPIROMETRIAS | L33: ELECTROCARDIOGRAMA | AK33: ='GRAFICAS OCULTAR'!AS3 -> MODERADAS | AL33: ='GRAFICAS OCULTAR'!AT3 -> 1 | AU33: ='GRAFICAS OCULTAR'!AJ5 -> Alto | AV33: ='GRAFICAS OCULTAR'!AK5 -> 20
A34: TABAQUISMO | L34: SIN DATOS PATOLOGICOS APARENTES | M34: 45 | AK34: ='GRAFICAS OCULTAR'!AS4 -> ABUNDANTES | AL34: ='GRAFICAS OCULTAR'!AT4 -> 0 | AU34: ='GRAFICAS OCULTAR'!AJ6 -> Muy alto | AV34: ='GRAFICAS OCULTAR'!AK6 -> 2
A35: NEGADO | B35: 51 | L35: CASOS DE SEGUIMIENTO | M35: 15 | AU35: ='GRAFICAS OCULTAR'!AJ7 -> Etiquetas de fila | AV35: ='GRAFICAS OCULTAR'!AK7 -> Cuenta de TRIG
A36: POSITIVO | B36: 17
A38: TRAUMA ACUSTICO
A39: CIPP | Y39: RADIOGRAFÍA TORAX | AK39: HEMOGLOBINA
A40: <10% | B40: ='GRAFICAS OCULTAR'!G2 -> 12 | Y40: Riesgos muy Altos | AK40: Bajo | AL40: 1
A41: 11-19% | B41: ='GRAFICAS OCULTAR'!G3 -> 1 | Y41: Riesgos Altos | AK41: Normal | AL41: 67
A42: >20% | B42: ='GRAFICAS OCULTAR'!G4 -> 1 | Y42: Casos p/seguimiento | Z42: 6 | AK42: Alto | AU42: QS6
...

Sheet GRAFICAS OCULTAR
A1: Etiquetas de fila | B1: Cuenta de DX | C1: Etiquetas de fila | D1: Cuenta de TABAQUISMO | F1: HBC CIPP | I1: <1 AÑO | J1: 1 | O1: ESCOLIOSIS | R1: LORDOSIS | U1: BASCULACION PELVICA | AJ1: TRIGLICERIDOS | AM1: ACIDO URICO | AP1: CRISTALES | AS1: BACTERIAS | AV1: HEMOGLOBINA
A2: NORMAL | B2: 30 | C2: NEGADO | D2: 51 | F2: <10% | G2: =SUMIFS(L5:L61,K5:K61,">=-9",K5:K61,"<=10,99") -> 12 | I2: 1-5 AÑOS | J2: 12 | K2: DX | L2: (Varios elementos) | O2: NORMAL | P2: =SUMIFS(P8:P32,O8:O32,">=0",O8:O32,"<=0") -> 0 | R2: DISMINUIDA | S2: =SUMIFS(S8:S48,R8:R48,">=0",R8:R48,"<=20") -> 0 | U2: NORMAL | V2: =SUMIFS(V8:V48,U8:U48,">=0",U8:U48,"<=1,0") -> 61 | X2: LEUCOCITOS | AA2: PLAQUETAS | AD2: GLUCOSA | AG2: COLESTEROL | AJ2: Baja | AK2: =SUMIFS(AK8:AK617,AJ8:AJ617,">=0,1",AJ8:AJ617,"<=39,9") -> 0 | AM2: NORMAL | AN2: =SUMIFS(AN8:AN617,AM8:AM617,">=3,6",AM8:AM617,"<=7,7") -> 58 | AP2: SIN CRISTALES | AQ2: 17 | AS2: AUSENTES/ESCASAS | AT2: 67 | AV2: NO DIABETICO | AW2: =SUMIFS(AW8:AW617,AV8:AV617,">=0.1",AV8:AV617,"<=6") -> 0
A3: FATIGA AUDITIVA | B3: 23 | C3: POSITIVO | D3: 17 | F3: 11-19% | G3: =SUMIFS(L5:L61,K5:K61,">=11",K5:K61,"<=19,99") -> 1 | I3: 10-20 AÑOS | J3: 1 | O3: ESCOLIOSIS LEVE | P3: =SUMIFS(P8:P32,O8:O32,">=1",O8:O32,"<=5") -> 61 | R3: NORMAL | S3: =SUMIFS(S8:S48,R8:R48,">=21",R8:R48,"<=39") -> 29 | U3: LEVE | V3: =SUMIFS(V8:V48,U8:U48,">=1,1",U8:U48,"<=5,0") -> 7 | X3: NORMAL | Y3: =SUMIFS(Y8:Y80,X8:X80,">=3,5",X8:X80,"<=10,3") -> 66 | AA3: BAJO | AB3: =SUMIFS(AB8:AB80,AA8:AA80,">=0,1",AA8:AA80,"<=149,9") -> 1 | AD3: Baja | AE3: =SUMIFS(AE8:AE617,AD8:AD617,">=1",AD8:AD617,"<=60,9") -> 0 | AG3: Normal | AH3: =SUMIFS(AH8:AH616,AG8:AG616,">=0,1",AG8:AG616,"<=200,9") -> 56 | AJ3: Normal | AK3: =SUMIFS(AK8:AK617,AJ8:AJ617,">=40",AJ8:AJ617,"<=160,9") -> 38 | AM3: ALTO | AN3: =SUMIFS(AN8:AN617,AM8:AM617,">=7,79",AM8:AM617,"<=1000000000000") -> 8 | AP3: PRESENCIA DE CRISTALES | AQ3: 51 | AS3: MODERADAS | AT3: 1 | AV3: DIABETICO EN CONTROL | AW3: =SUMIFS(AW9:AW618,AV9:AV618,">=6.1",AV9:AV618,"<=7") -> 0
A4: LEVE TA | B4: 12 | C4: Total general | D4: 68 | F4: >20% | G4: =SUMIFS(L5:L61,K5:K61,">=20",K5:K61,"<=100") -> 1 | I4: 21-30 AÑOS | K4: Etiquetas de fila | L4: Cuenta de % HBC | O4: ESCOLIOSIS MODERADA | P4: =SUMIFS(P8:P32,O8:O32,">=6",O8:O32,"<=9") -> 7 | R4: AUMENTADA | S4: =SUMIFS(S8:S49,R8:R49,">=40",R8:R49,"<=49") -> 36 | U4: ALTA | V4: =SUMIFS(V8:V48,U8:U48,">=5,1",U8:U48,"<=100") -> 0 | X4: ALTO | Y4: =SUMIFS(Y8:Y80,X8:X80,">=10,4",X8:X80,"<=100000") -> 2 | AA4: NORMAL | AB4: =SUMIFS(AB8:AB231,AA8:AA231,">=150",AA8:AA231,"<=450") -> 67 | AD4: Normal | AE4: =SUMIFS(AE8:AE617,AD8:AD617,">=60",AD8:AD617,"<=110,9") -> 66 | AG4: Moderado | AH4: =SUMIFS(AH8:AH617,AG8:AG617,">=201",AG8:AG617,"<=240,9") -> 10 | AJ4: Limite Alto | AK4: =SUMIFS(AK8:AK617,AJ8:AJ617,">=161",AJ8:AJ617,"<=199,9") -> 8 | AM4: BAJO | AN4: =SUMIFS(AN8:AN617,AM8:AM617,">=0,1",AM8:AM617,"<=3,59") -> 2 | AS4: ABUNDANTES | AV4: RIESGO | AW4: =SUMIFS(AW8:AW617,AV8:AV617,">=7.1",AV8:AV617,"<=1000") -> 0
A5: NO RELACIONADA A RUIDO LABORAL | B5: 1 | E5: DX | F5: (Todas) | K5: 6.63 | L5: 1 | O5: ESCOLIOSIS GRAVE | P5: =SUMIFS(P8:P32,O8:O32,">=10",O8:O32,"<100") -> 0 | R5: HIPERLORDOSIS | S5: =SUMIFS(S8:S50,R8:R50,">=50",R8:R50,"<=100") -> 3 | X5: BAJO | Y5: =SUMIFS(Y8:Y80,X8:X80,">=0,1",X8:X80,"<=3,4") -> 0 | AA5: ALTO | AB5: =SUMIFS(AB8:AB80,AA8:AA80,">=451",AA8:AA80,"<=100000000000000") -> 0 | AD5: Alterada | AE5: =SUMIFS(AE8:AE617,AD8:AD617,">=111",AD8:AD617,"<=125,9") -> 1 | AG5: Alto | AH5: =SUMIFS(AH8:AH617,AG8:AG617,">=241",AG8:AG617,"<=1000000") -> 2 | AJ5: Alto | AK5: =SUMIFS(AK8:AK617,AJ8:AJ617,">=200",AJ8:AJ617,"<=499,9") -> 20
A6: MODERADA TA | B6: 2 | G6: DX | H6: (Varios elementos) | K6: 10.38 | L6: 1 | AD6: PB diabetes | AE6: =SUMIFS(AE8:AE617,AD8:AD617,">=126",AD8:AD617,"<=1000000") -> 1 | AJ6: Muy alto | AK6: =SUMIFS(AK8:AK617,AJ8:AJ617,">=500",AJ8:AJ617,"<=100000000000000") -> 2
A7: Total general | B7: 68 | E7: Etiquetas de fila | F7: Cuenta de AREA/ PUESTO | K7: 13.5 | L7: 1 | O7: Etiquetas de fila | P7: Cuenta de GRADO DE ESCOLIOSIS(°) | R7: Etiquetas de fila | S7: Cuenta de GRADO DE LORDOSIS(°) | U7: Etiquetas de fila | V7: Cuenta de BASCULACIÓN PELVICA (cms) | X7: Etiquetas de fila | Y7: Cuenta de BH LEU | AA7: Etiquetas de fila | AB7: Cuenta de BH PLA | AD7: Etiquetas de fila | AE7: Cuenta de GLUC | AG7: Etiquetas de fila | AH7: Cuenta de COL | AJ7: Etiquetas de fila | AK7: Cuenta de TRIG | AM7: Etiquetas de fila | AN7: Cuenta de AU | AP7: Etiquetas de fila | AQ7: Cuenta de CRISTALES EGO | AS7: Etiquetas de fila | AT7: Cuenta de EGO BAC
E8: ALMACEN | F8: 1 | G8: Etiquetas de fila | H8: Cuenta de ANTIGÜEDAD | K8: 8 | L8: 2 | O8: 2 | P8: 6 | R8: 28 | S8: 1 | U8: 1 | V8: 4 | X8: 5.6 | Y8: 2 | AA8: 331 | AB8: 2 | AD8: (en blanco) | AG8: (en blanco) | AJ8: (en blanco) | AM8: (en blanco) | AP8: (en blanco) | AS8: (en blanco)
E9: LOGISTICA | F9: 3 | G9: 11 MESES | H9: 1 | K9: 9.13 | L9: 1 | O9: 3 | P9: 23 | R9: 30 | S9: 7 | U9: 1.4 | V9: 3 | X9: (en blanco) | AA9: (en blanco) | AD9: 74.3 | AE9: 1 | AG9: 208.8 | AH9: 2 | AJ9: 80.3 | AK9: 1 | AM9: 9.8 | AN9: 1 | AP9: URATOS AMORFOS ESCASOS | AQ9: 31 | AS9: AUSENTES | AT9: 6
E10: MANTENIMIENTO | F10: 6 | G10: 13 AÑOS | H10: 1 | K10: 4.63 | L10: 1 | O10: 4 | P10: 19 | R10: 32 | S10: 3 | U10: 1.8 | V10: 2 | X10: 7.6 | Y10: 1 | AA10: 217 | AB10: 1 | AD10: 82.6 | AE10: 2 | AG10: 212.6 | AH10: 1 | AJ10: 166.2 | AK10: 1 | AM10: 7.7 | AN10: 4 | AP10: URATOS AMORFOS MODERADOS | AQ10: 7 | AS10: ESCASAS | AT10: 61
E11: SEGURIDAD E HIGIENE | F11: 1 | G11: 3 AÑOS | H11: 3 | K11: 22 | L11: 1 | O11: 5 | P11: 13 | R11: 34 | S11: 4 | U11: 2 | V11: 2 | X11: 7.7 | Y11: 5 | AA11: 312 | AB11: 1 | AD11: 78.6 | AE11: 3 | AG11: 164.3 | AH11: 1 | AJ11: 210 | AK11: 1 | AM11: 6.6 | AN11: 4 | AP11: FOSFATOS AMORFOS ABUNDANTES | AQ11: 2 | AS11: MODERADAS | AT11: 1
E12: (en blanco) | G12: 4 AÑOS | H12: 2 | K12: 2.5 | L12: 1 | O12: 6 | P12: 5 | R12: 36 | S12: 10 | U12: 0 | V12: 57 | X12: 5.8 | Y12: 4 | AA12: 173 | AB12: 1 | AD12: 64.1 | AE12: 1 | AG12: 148 | AH12: 1 | AJ12: 112.4 | AK12: 1 | AM12: 7.1 | AN12: 3 | AP12: FOSFATOS AMORFOS ESCASOS | AQ12: 2 | AS12: Total general | AT12: 68
E13: SOLDADURA | F13: 22 | G13: 2 AÑOS | H13: 1 | K13: 5.25 | L13: 1 | O13: 7 | P13: 1 | R13: 38 | S13: 3 | U13: Total general | V13: 68 | X13: 6.2 | Y13: 2 | AA13: 226 | AB13: 1 | AD13: 69.3 | AE13: 1 | AG13: 196.1 | AH13: 1 | AJ13: 225.2 | AK13: 1 | AM13: 7.5 | AN13: 2 | AP13: URATOS AMORFOS ABUNDANTES | AQ13: 4
E14: MAQUINADOS | F14: 19 | G14: 4 AÑOS | H14: 2 | K14: 6.38 | L14: 1 | O14: 9 | P14: 1 | R14: 40 | S14: 14 | X14: 5.4 | Y14: 3 | AA14: 251 | AB14: 2 | AD14: 84.5 | AE14: 1 | AG14: 188.6 | AH14: 1 | AJ14: 128.3 | AK14: 1 | AM14: 7 | AN14: 2 | AP14: OXALATOS DE CALCIO DIHIDRATADOS ESCASOS | AQ14: 3
E15: ALMACEN F5 | F15: 5 | G15: 4 AÑOS 10 MESES | H15: 1 | K15: 6.25 | L15: 1 | O15: Total general | P15: 68 | R15: 42 | S15: 3 | X15: 8.6 | Y15: 2 | AA15: 276 | AB15: 2 | AD15: 67.2 | AE15: 1 | AG15: 140.6 | AH15: 1 | AJ15: 75.7 | AK15: 1 | AM15: 5.8 | AN15: 3 | AP15: OXALATOS DE CALCIO DIHIDRATADOS ABUNDANTES | AQ15: 1
E16: PINTURA | F16: 9 | G16: 3 AÑOS | H16: 1 | K16: 7.75 | L16: 1 | R16: 44 | S16: 8 | X16: 6.8 | Y16: 1 | AA16: 339 | AB16: 1 | AD16: 70.4 | AE16: 1 | AG16: 145.6 | AH16: 1 | AJ16: 151.2 | AK16: 1 | AM16: 6 | AN16: 3 | AP16: OXALATOS DE CALCIO DIHIDRATADOS MODERADOS | AQ16: 1
E17: Total general | F17: 66 | G17: 4 AÑOS 4 MESES | H17: 1 | K17: 7.5 | L17: 1 | R17: 45 | S17: 6 | X17: 8 | Y17: 1 | AA17: 203 | AB17: 2 | AD17: 89 | AE17: 1 | AG17: 146.4 | AH17: 1 | AJ17: 177.2 | AK17: 1 | AM17: 6.2 | AN17: 1 | AP17: Total general | AQ17: 51
G18: 3 AÑOS 11 MESES | H18: 1 | K18: Total general | L18: 14 | R18: 46 | S18: 1 | X18: 7.1 | Y18: 1 | AA18: 220 | AB18: 1 | AD18: 81.9 | AE18: 1 | AG18: 177.2 | AH18: 1 | AJ18: 217.6 | AK18: 1 | AM18: 5.6 | AN18: 3
G19: Total general | H19: 14 | R19: 48 | S19: 4 | X19: 7.4 | Y19: 1 | AA19: 271 | AB19: 1 | AD19: 74.8 | AE19: 1 | AG19: 116.1 | AH19: 1 | AJ19: 60.6 | AK19: 1 | AM19: 5.3 | AN19: 4
R20: 50 | S20: 1 | X20: 7.3 | Y20: 2 | AA20: 215 | AB20: 1 | AD20: 80 | AE20: 2 | AG20: 164.2 | AH20: 2 | AJ20: 65.3 | AK20: 1 | AM20: 6.4 | AN20: 3
R21: 58 | S21: 1 | X21: 6.6 | Y21: 2 | AA21: 192 | AB21: 1 | AD21: 83 | AE21: 1 | AG21: 153.9 | AH21: 1 | AJ21: 92.7 | AK21: 1 | AM21: 7.3 | AN21: 2
R22: 52 | S22: 1 | X22: 4.9 | Y22: 1 | AA22: 193 | AB22: 1 | AD22: 84.3 | AE22: 2 | AG22: 200.9 | AH22: 1 | AJ22: 117 | AK22: 1 | AM22: 8.6 | AN22: 1
R23: 26 | S23: 1 | X23: 6.9 | Y23: 2 | AA23: 366 | AB23: 1 | AD23: 85.2 | AE23: 2 | AG23: 164.1 | AH23: 1 | AJ23: 208.5 | AK23: 1 | AM23: 8 | AN23: 3
A24: Etiquetas de fila | B24: Cuenta de ESPIROMETRIA | R24: Total general | S24: 68 | X24: 3.7 | Y24: 1 | AA24: 216 | AB24: 1 | AD24: 77.4 | AE24: 2 | AG24: 229.3 | AH24: 1 | AJ24: 202.5 | AK24: 1 | AM24: 4.3 | AN24: 2
A25: NORMAL | B25: 42 | X25: 5.7 | Y25: 1 | AA25: 350 | AB25: 1 | AD25: 74.9 | AE25: 2 | AG25: 196.6 | AH25: 1 | AJ25: 253.1 | AK25: 1 | AM25: 6.8 | AN25: 2
A26: PATRÓN ESPIROMÉTRICO RESTRICTIVO LEVE | B26: 17 | X26: 4.6 | Y26: 1 | AA26: 295 | AB26: 1 | AD26: 78.2 | AE26: 2 | AG26: 183.3 | AH26: 1 | AJ26: 129 | AK26: 1 | AM26: 4 | AN26: 1
A27: PATRÓN ESPIROMÉTRICO OBSTRUCTIVO | B27: 1 | X27: 5.5 | Y27: 2 | AA27: 145 | AB27: 1 | AD27: 89.2 | AE27: 1 | AG27: 175.4 | AH27: 1 | AJ27: 79.7 | AK27: 1 | AM27: 6.9 | AN27: 2
A28: Total general | B28: 60 | X28: 6.1 | Y28: 3 | AA28: 248 | AB28: 2 | AD28: 86.4 | AE28: 1 | AG28: 155 | AH28: 1 | AJ28: 81.6 | AK28: 1 | AM28: 4.5 | AN28: 2
X29: 6.4 | Y29: 2 | AA29: 157 | AB29: 1 | AD29: 78.7 | AE29: 1 | AG29: 181 | AH29: 1 | AJ29: 161.2 | AK29: 2 | AM29: 6.1 | AN29: 2
X30: 10.4 | Y30: 1 | AA30: 284 | AB30: 2 | AD30: 78.3 | AE30: 1 | AG30: 169.1 | AH30: 1 | AJ30: 82.1 | AK30: 1 | AM30: 4.8 | AN30: 2
X31: 9.4 | Y31: 2 | AA31: 162 | AB31: 1 | AD31: 83.8 | AE31: 1 | AG31: 169.2 | AH31: 1 | AJ31: 97 | AK31: 1 | AM31: 3.9 | AN31: 1
X32: 6.7 | Y32: 2 | AA32: 187 | AB32: 1 | AD32: 69.8 | AE32: 1 | AG32: 238.7 | AH32: 1 | AJ32: 134 | AK32: 1 | AM32: 6.3 | AN32: 2
X33: 7 | Y33: 1 | AA33: 165 | AB33: 1 | AD33: 125.8 | AE33: 1 | AG33: 161.9 | AH33: 1 | AJ33: 56.1 | AK33: 1 | AM33: 8.4 | AN33: 1
X34: 7.2 | Y34: 2 | AA34: 243 | AB34: 1 | AD34: 82.7 | AE34: 1 | AG34: 149 | AH34: 1 | AJ34: 543.6 | AK34: 1 | AM34: 5.7 | AN34: 2
X35: 6 | Y35: 2 | AA35: 222 | AB35: 1 | AD35: 74.6 | AE35: 1 | AG35: 146.3 | AH35: 1 | AJ35: 52.5 | AK35: 1 | AM35: 8.2 | AN35: 1
X36: 7.8 | Y36: 2 | AA36: 329 | AB36: 1 | AD36: 75.9 | AE36: 1 | AG36: 144.9 | AH36: 1 | AJ36: 102.5 | AK36: 1 | AM36: 6.5 | AN36: 3
X37: 4.7 | Y37: 1 | AA37: 285 | AB37: 2 | AD37: 92.6 | AE37: 1 | AG37: 164.9 | AH37: 1 | AJ37: 66.6 | AK37: 1 | AM37: 5.9 | AN37: 1
X38: 6.5 | Y38: 1 | AA38: 369 | AB38: 1 | AD38: 85.1 | AE38: 2 | AG38: 165.1 | AH38: 1 | AJ38: 99.5 | AK38: 1 | AM38: 4.7 | AN38: 1
X39: 4.4 | Y39: 1 | AA39: 342 | AB39: 1 | AD39: 83.3 | AE39: 2 | AG39: 191.1 | AH39: 1 | AJ39: 142.1 | AK39: 1 | AM39: 3 | AN39: 1
X40: 8.5 | Y40: 2 | AA40: 297 | AB40: 1 | AD40: 80.3 | AE40: 2 | AG40: 144.7 | AH40: 1 | AJ40: 129.2 | AK40: 1 | AM40: 5.5 | AN40: 1
...

Sheet Hoja3
A1: AGUDEZA VISUAL
A2: 0 | B2: N/A
A3: 1 | B3: DISMINUIDA SIN USO DE LENTES
A4: 2 | B4: NORMAL
A5: 3 | B5: DISMINUIDA CORREGIDA
A6: 4 | B6: DISMINUIDA NO CORREGIDA
A8: CAMPOS VISUALES
A9: 0 | B9: N/A
A10: 1 | B10: NORMAL
A11: 2 | B11: DISMINUIDO
A13: DISCRIMINACIÓN DE COLORES
A14: 0 | B14: N/A
A15: 1 | B15: NORMAL
A16: 2 | B16: DISCROMATOPSIA
A18: AUDIOMETRÍA
A19: 0 | B19: N/A
A20: 1 | B20: Audición Normal
A21: 2 | B21: Audición Normal, Datos de Fatiga Auditiva
A22: 3 | B22: Hipoacusia Neurosensorial, Leve , Secundario a Trauma Acústico crónico por ruido
A23: 4 | B23: Hipoacusia Neurosensorial, Moderada , Secundario a Trauma Acústico crónico por ruido
A24: 5 | B24: Hipoacusia Neurosensorial, Grave , Secundario a Trauma Acústico crónico por ruido
A25: 6 | B25: Hipoacusia Neurosensorial, Profunda , Secundario a Trauma Acústico crónico por ruido
A26: 7 | B26: Hipoacusia Mixta, Leve , Secundario a Trauma Acústico crónico por ruido
A27: 8 | B27: Hipoacusia Mixta, Moderada , Secundario a Trauma Acústico crónico por ruido
A28: 9 | B28: Hipoacusia Mixta, Grave , Secundario a Trauma Acústico crónico por ruido
A29: 10 | B29: Hipoacusia Mixta, Profunda , Secundario a Trauma Acústico crónico por ruido
A30: 11 | B30: Hipoacusia Conductiva, Leve , De etiología a determinar
... A45: 26 | B45: Hipoacusia Neurosensorial, Profunda , Secundario a Presbiacusia
A48: ESPIROMETRÍA
B49: N/A
A50: 1 | B50: NORMAL
A51: 2 | B51: PATRÓN ESPIROMÉTRICO RESTRICTIVO LEVE
A52: 3 | B52: PATRÓN ESPIROMÉTRICO RESTRICTIVO MODERADO
A53: 4 | B53: PATRÓN ESPIROMÉTRICO OBSTRUCTIVO
A54: 4 | B54: PATRÓN ESPIROMÉTRICO NO DIAGNOSTICABLE
A56: TOXICOLOGICO
A57: 1 | B57: NEGATIVO EN TODOS LOS PANELES
A58: 2 | B58: POSITIVO A MARIHUANA
A59: 3 | B59: POSITIVO A COCOCAINA
A60: 4 | B60: POSITIVO A METANFETAMINAS
...
